Workbook

Sheet WE 12.10.25
B1: POSTED AND RECONCILED TO SAGE ON :
B3: MANAGER IN CHARGE :
C4: Monday | D4: Tuesday | E4: Wednesday | F4: Thursday | G4: Friday | H4: Saturday | I4: Sunday
C5: 45936 | D5: =C5+1 -> 45937 | E5: =D5+1 -> 45938 | F5: =E5+1 -> 45939 | G5: =F5+1 -> 45940 | H5: =G5+1 -> 45941 | I5: =H5+1 -> 45942 | J5: Total | K5: CBE | M5: Variance
B6: Sales
B7: Bar | C7: 2743.1 | D7: 2133.8 | E7: 5585.8 | F7: 5102.4 | G7: 4289 | H7: 7282.4 | I7: 3438.7 | J7: =SUM(C7:I7) -> 30575.2 | K7: 24857.89 | M7: =(K7*1.23)-J7 -> 0.0047
B8: Food | C8: 14716.6 | D8: 11908.4 | E8: 20283.8 | F8: 27637 | G8: 20118.71 | H8: 33317.9 | I8: 20403.7 | J8: =SUM(C8:I8) -> 148386.11 | K8: 130736.66 | M8: =(K8*1.135)-J8 -> -0.00090000001
B9: Wine | C9: 4938 | D9: 3206 | E9: 6282.5 | F9: 7440 | G9: 6383 | H9: 12526 | I9: 4896.5 | J9: =SUM(C9:I9) -> 45672 | K9: 37131.71 | M9: =(K9*1.23)-J9 -> 0.0033
B10: Service Charge | C10: 1030.16 | D10: 768.45 | E10: 2497.64 | F10: 3171.72 | G10: 1037.14 | H10: 1905.9 | I10: 898.92 | J10: =SUM(C10:I10) -> 11309.93 | K10: 9964.7 | L10: =J10-K10 -> 1345.23 | M10: =(K10*1.135)-J10 -> 0.0045
B11: Room Rental/Other | F11: 430.5 | H11: 32 | I11: 16 | J11: =SUM(C11:I11) -> 478.5 | K11: 389.02 | M11: =(K11*1.23)-J11 -> -0.0054
B12: DRINK OTHER | C12: 25.27 | D12: 1.46 | E12: 5.8 | F12: 6.28 | G12: 73.21 | H12: 51.28 | I12: 15.87 | J12: =SUM(C12:I12) -> 179.17 | K12: 145.67 | M12: =(K12*1.23)-J12 -> 0.0041
B13: Total | C13: =SUM(C7:C12) -> 23453.13 | D13: =SUM(D7:D12) -> 18018.11 | E13: =SUM(E7:E12) -> 34655.54 | F13: =SUM(F7:F12) -> 43787.9 | G13: =SUM(G7:G12) -> 31901.06 | H13: =SUM(H7:H12) -> 55115.48 | I13: =SUM(I7:I12) -> 29669.69 | J13: =SUM(C13:I13) -> 236600.91 | K13: =SUM(K7:K12) -> 203225.65
B15: Credit Card | C15: =+'CC bank '!E18 -> 22816.69 | D15: =+'CC bank '!F18 -> 17850.8 | E15: =+'CC bank '!G18 -> 23735.27 | F15: =+'CC bank '!H18 -> 22405.6 | G15: =+'CC bank '!I18 -> 29633.45 | H15: =+'CC bank '!J18 -> 45922.34 | I15: =+'CC bank '!K18 -> 27791.93 | J15: =SUM(C15:I15) -> 190156.08 | K15: ='CC bank '!L18 -> 190156.08 | M15: =J15-K15 -> 0
B16: Cash | C16: 740 | D16: 650 | E16: 1030 | F16: 2130 | G16: 2950 | H16: 4695 | I16: =3550 -> 3550 | J16: =SUM(C16:I16) -> 15745 | K16: 15745 | M16: =J16-K16 -> 0
B17: As per lodgement book (Monday & Thursday) | C17: 740 | D17: 650 | E17: 1030 | F17: 2130 | G17: 2950 | H17: 4695 | I17: 3550 | J17: =SUM(C17:I17) -> 15745 | K17: 15745 | M17: =J17-K17 -> 0
B18: Debtors | F18: 12496.25 | G18: 662.06 | I18: =290-150 -> 140 | J18: =SUM(C18:I18) -> 13298.31 | K18: 13448.31 | M18: =J18-K18 -> -150
B19: Debtors with Taste GV Sold | M19: =J19-K19 -> 0
B20: GV Redeemed | C20: =-'Physical GVs'!H4 -> 100 | D20: =-'Digital GVs'!H4 -> 265.3 | E20: =-'Physical GVs'!H9 -> 150 | F20: =-'Digital GVs'!H9 -> 200 | G20: =-'Physical GVs'!H19-'Digital GVs'!H15 -> 400 | H20: =-'Physical GVs'!H37-'Digital GVs'!H27 -> 2446.2 | I20: =-'Physical GVs'!H48-'Digital GVs'!H33 -> 318.9 | J20: =SUM(C20:I20) -> 3880.4 | K20: 3880.4 | L20: =J20-J21 -> 3230.4 | M20: =J20-K20 -> 0
B21: GV Sold (-) | C21: 0 | D21: 0 | E21: 0 | F21: ='Physical GVs'!H14 -> 150 | G21: 0 | H21: ='Physical GVs'!H24 -> 150 | I21: ='Physical GVs'!H44 -> 350 | J21: =SUM(C21:I21) -> 650 | K21: 650 | L21: =K20-K21 -> 3230.4 | M21: =K21-J21 -> 0
B22: Complimentary | C22: 209.8 | D22: 149.5 | E22: 339.9 | F22: 138 | G22: 183.71 | H22: 86.4 | I22: 41.3 | J22: =SUM(C22:I22) -> 1148.61 | K22: 1148.61 | M22: =J22-K22 -> 0
B23: SOT Pay REDEEMED/Deposit REDEEMED | C23: 1000 | E23: =8000+2299.95 -> 10299.95 | F23: 7750 | H23: 4875 | J23: =SUM(C23:I23) -> 23924.95 | K23: =21625+2299.95 -> 23924.95 | M23: =J23-K23 -> 0
B24: Deposits Taken (-) | J24: =SUM(C24:I24) -> 0 | M24: =J24-K24 -> 0
B25: CREDIT CARD TIPS | C25: ='CC TIPS'!B6 -> 1434.43 | D25: ='CC TIPS'!B15 -> 878.79 | E25: ='CC TIPS'!B26 -> 916.57 | F25: ='CC TIPS'!B35 -> 1181.45 | G25: ='CC TIPS'!B44-50 -> 1973.06 | H25: ='CC TIPS'!B54 -> 2711.2 | I25: ='CC TIPS'!B63 -> 2083.29 | J25: =SUM(C25:I25) -> 11178.79 | K25: ='CC TIPS'!B6+'CC TIPS'!B15+'CC TIPS'!B26+'CC TIPS'!B35+'CC TIPS'!B44+'CC TIPS'!B54+'CC TIPS'!B63 -> 11228.79 | L25: ='CC TIPS'!B6+'CC TIPS'!B15+'CC TIPS'!B26+'CC TIPS'!B35+'CC TIPS'!B44+'CC TIPS'!B54+'CC TIPS'!#REF! -> #ERROR! | M25: =J25-K25 -> -50
B26: ROUNDED BILLS | G26: 4.3 | H26: 35 | I26: 47 | J26: =SUM(C26:I26) -> 86.3 | L26: ENTER AS SERVICE CHARGE | M26: =J26-K26 -> 86.3
B27: 20% discount | C27: 28.4 | G27: 62.6 | I27: 61.52 | J27: =SUM(C27:I27) -> 152.52 | K27: 152.52 | M27: =J27-K27 -> 0
B28: loyalty | I28: 150 | J28: =SUM(C28:I28) -> 150 | M28: =J28-K28 -> 150
B29: Refund - OVERCHARGED DAY REDUCE/ REFUND DAY ADD BACK | J29: =SUM(C29:I29) -> 0 | M29: =J29-K29 -> 0
J30: =SUM(C30:I30) -> 0 | M30: =J30-K30 -> 0
B31: Petty Cash | J31: =SUM(C31:I31) -> 0 | M31: =J31-K31 -> 0
B32: ADJUSTMENTS FOR VARIANCES | I32: 46.8 | J32: =SUM(C32:I32) -> 46.8 | M32: =J32-K32 -> 46.8
B33: Total | C33: =C15+C16+C18+C20-C21+C22+C23-C24-C25-C26+C27+C28+C31+C29+C19+C32 -> 23460.46 | D33: =D15+D16+D18+D20-D21+D22+D23-D24-D25-D26+D27+D28+D31+D29+D19+D32 -> 18036.81 | E33: =E15+E16+E18+E20-E21+E22+E23-E24-E25-E26+E27+E28+E31+E29+E19+E32 -> 34638.55 | F33: =F15+F16+F18+F20-F21+F22+F23-F24-F25-F26+F27+F28+F31+F29+F19+F32 -> 43788.4 | G33: =G15+G16+G18+G20-G21+G22+G23-G24-G25-G26+G27+G28+G31+G29+G19+G32+G24 -> 31914.46 | H33: =H15+H16+H18+H20-H21+H22+H23-H24-H25-H26+H27+H28+H31+H29+H19+H32-H16+H17 -> 55128.74 | I33: =I15+I16+I18+I20-I21+I22+I23-I24-I25-I26+I27+I28+I31+I29+I19+I32 -> 29620.16 | J33: =SUM(C33:I33) -> 236587.58 | M33: =J33-K33 -> 236587.58
J34: =SUM(C34:I34) -> 0
B35: Variance | C35: =C33-C13 -> 7.33 | D35: =D33-D13 -> 18.7 | E35: =E33-E13 -> -16.99 | F35: =F33-F13 -> 0.5 | G35: =G33-G13 -> 13.4 | H35: =H33-H13 -> 13.26 | I35: =I33-I13 -> -49.53 | J35: =J33-J13 -> -13.33 | M35: =J35 -> -13.33
M36: =J36-K36 -> 0
B37: CC AS PER INPUT SHEET | C37: =C15-C25 -> 21382.26 | D37: =D15-D25 -> 16972.01 | E37: =E15-E25 -> 22818.7 | F37: =F15-F25 -> 21224.15 | G37: =G15-G25 -> 27660.39 | H37: =H15-H25 -> 43211.14 | I37: =I15-I25 -> 25708.64 | J37: =J15-J25 -> 178977.29 | K37: =K15-K25 -> 178927.29 | M37: =J37-K37 -> 50
B38: CC AS PER SALES SUMMARY -CBE | C38: 21382.26 | D38: 16972.01 | E38: 22808.7 | F38: 21224.15 | G38: 29633.45 | H38: 43361.14 | I38: 25708.64 | J38: =SUM(C38:I38) -> 181090.35 | M38: =J38-K38 -> 181090.35
B39: VARIANCE | C39: =C37-C38 -> 0 | D39: =D37-D38 -> 0 | E39: =E37-E38 -> 10 | F39: =F37-F38 -> 0 | G39: =G37-G38 -> -1973.06 | H39: =H37-H38 -> -150 | I39: =I37-I38 -> 0 | J39: =J37-J38 -> -2113.06
C41: =C35-C39 -> 7.33 | D41: =D35-D39 -> 18.7 | E41: =E35-E39 -> -26.99 | F41: =F35-F39 -> 0.5 | G41: =G35-G39 -> 1986.46 | H41: =H35-H39 -> 163.26 | I41: =I35-I39 -> -49.53 | J41: =SUM(C41:I41) -> 2099.73 | M41: =J41-K41 -> 2099.73
B42: Adjusted for GV Variances | C42: =C41 -> 7.33 | D42: =D41 -> 18.7 | E42: =E41 -> -26.99 | F42: =F41 -> 0.5 | G42: =G41 -> 1986.46 | H42: =H41 -> 163.26 | I42: =I41 -> -49.53 | J42: =SUM(C42:I42) -> 2099.73 | M42: =J42-K42 -> 2099.73
B44: DEBTORS/DEPOSITS ADJUSTED | C44: ROOM /OTHER 4120 | D44: FOOD 4008 | E44: DRINK 4009 | F44: SC 2102 | G44: Total | H44: INVOICE
...

Sheet IMPORT SHEET
A1: Type | B1: Account reference | C1: Nominal A/C Ref | D1: Date | E1: Ref | F1: Details | G1: Net Amount | H1: Tax code | I1: Tax amount
A2: SI | B2: F2025 | C2: 4006 | D2: ='WE 12.10.25'!I5 -> 45942 | E2: WE 12.10.25 | F2: ='WE 12.10.25'!B101 & 'IMPORT SHEET'!E2 -> FIRE FOOD LUNCH WE 12.10.25 | G2: ='WE 12.10.25'!G101 -> 20559 | H2: ='WE 12.10.25'!I101 -> T3 | I2: ='WE 12.10.25'!H101 -> 2775.465
A3: SI | B3: F2025 | C3: 4008 | D3: =D2 -> 45942 | E3: =E2 -> WE 12.10.25 | F3: ='WE 12.10.25'!B102&'IMPORT SHEET'!E3 -> FIRE FOOD DINNER WE 12.10.25 | G3: ='WE 12.10.25'!G102 -> 89217.749 | H3: ='WE 12.10.25'!I102 -> T3 | I3: ='WE 12.10.25'!H102 -> 12044.396
A4: SI | B4: F2025 | C4: 4007 | D4: =D3 -> 45942 | E4: =E3 -> WE 12.10.25 | F4: ='WE 12.10.25'!B104&'IMPORT SHEET'!E4 -> FIRE DRINK LUNCH WE 12.10.25 | G4: ='WE 12.10.25'!G104 -> 8761 | H4: ='WE 12.10.25'!I104 -> T1 | I4: ='WE 12.10.25'!H104 -> 2015.03
A5: SI | B5: F2025 | C5: 4009 | D5: =D4 -> 45942 | E5: =E4 -> WE 12.10.25 | F5: ='WE 12.10.25'!B105&'IMPORT SHEET'!E5 -> FIRE DRINK DINNER WE 12.10.25 | G5: ='WE 12.10.25'!G105 -> 46024.61 | H5: ='WE 12.10.25'!I105 -> T1 | I5: ='WE 12.10.25'!H105 -> 10585.66
A6: SI | B6: F2025 | C6: 2102 | D6: =D5 -> 45942 | E6: =E5 -> WE 12.10.25 | F6: ='WE 12.10.25'!B96&'IMPORT SHEET'!E6 -> 12.5% SERVICE CHARGE WE 12.10.25 | G6: ='WE 12.10.25'!G96 -> 8341.4273 | H6: ='WE 12.10.25'!I96 -> T3 | I6: ='WE 12.10.25'!H96 -> 1126.0927
A7: SI | B7: F2025 | C7: 4170 | D7: =D6 -> 45942 | E7: =E6 -> WE 12.10.25 | F7: ='WE 12.10.25'!B97&'IMPORT SHEET'!E7 -> FIRE DRINK TAKE AWAY WE 12.10.25 | G7: ='WE 12.10.25'!G97 -> 145.66667 | H7: ='WE 12.10.25'!I97 -> T1 | I7: ='WE 12.10.25'!H97 -> 33.503333
A8: SI | B8: F2025 | C8: 4120 | D8: =D7 -> 45942 | E8: =E7 -> WE 12.10.25 | F8: ='WE 12.10.25'!B98&'IMPORT SHEET'!E8 -> ROOM HIRE / OTHER WE 12.10.25 | G8: ='WE 12.10.25'!G98 -> 39.02439 | H8: ='WE 12.10.25'!I98 -> T1 | I8: ='WE 12.10.25'!H98 -> 8.9756098
A9: SI | B9: F2025 | C9: 2102 | D9: =D8 -> 45942 | E9: =E8 -> WE 12.10.25 | F9: ='WE 12.10.25'!B25&'IMPORT SHEET'!E9 -> CREDIT CARD TIPS WE 12.10.25 | G9: ='WE 12.10.25'!J25 -> 11178.79 | H9: T9 | I9: 0
A10: SI | B10: F2025 | C10: 2102 | D10: =D9 -> 45942 | E10: =E9 -> WE 12.10.25 | F10: ='WE 12.10.25'!B26&'IMPORT SHEET'!E10 -> ROUNDED BILLS WE 12.10.25 | G10: ='WE 12.10.25'!J26 -> 86.3 | H10: T9 | I10: 0
A11: SC | B11: F2025 | C11: 5170 | D11: =D10 -> 45942 | E11: =E10 -> WE 12.10.25 | F11: ='WE 12.10.25'!$C$108&'IMPORT SHEET'!E11 -> FIRE FOOD COMPS WE 12.10.25 | G11: ='WE 12.10.25'!C136 -> 831.3 | H11: ='WE 12.10.25'!C138 -> T9 | I11: 0
A12: SC | B12: F2025 | C12: 5170 | D12: =D11 -> 45942 | E12: =E11 -> WE 12.10.25 | F12: ='WE 12.10.25'!$D$108&'IMPORT SHEET'!E12 -> FIRE DRINK COMPS WE 12.10.25 | G12: ='WE 12.10.25'!D136 -> 317.3 | H12: ='WE 12.10.25'!D138 -> T9 | I12: 0
A13: SC | B13: F2025 | C13: 7900 | D13: =D12 -> 45942 | E13: =E12 -> WE 12.10.25 | F13: ='WE 12.10.25'!D158&'IMPORT SHEET'!E13 -> FIRE FOOD LOYALTY WE 12.10.25 | G13: ='WE 12.10.25'!D166 -> 99.118943 | H13: ='WE 12.10.25'!D140 -> T3 | I13: ='WE 12.10.25'!D168 -> 13.381057
A14: SC | B14: F2025 | C14: 7900 | D14: =D13 -> 45942 | E14: =E13 -> WE 12.10.25 | F14: ='WE 12.10.25'!E158&'IMPORT SHEET'!E14 -> FIRE DRINK LOYALTY WE 12.10.25 | G14: ='WE 12.10.25'!E166 -> 30.487805 | H14: ='WE 12.10.25'!E140 -> T1 | I14: ='WE 12.10.25'!E168 -> 7.0121951
A15: SC | B15: F2025 | C15: 4008 | D15: =D14 -> 45942 | E15: =E14 -> WE 12.10.25 | F15: ='WE 12.10.25'!D141&'IMPORT SHEET'!E15 -> FIRE FOOD DISCOUNT WE 12.10.25 | G15: ='WE 12.10.25'!D154 -> 100.78414 | H15: ='WE 12.10.25'!D157 -> T3 | I15: ='WE 12.10.25'!$D$156 -> 13.605859
A16: SC | B16: F2025 | C16: 4009 | D16: =D15 -> 45942 | E16: =E15 -> WE 12.10.25 | F16: ='WE 12.10.25'!E141&'IMPORT SHEET'!E16 -> FIRE DRINK DISCOUNT WE 12.10.25 | G16: ='WE 12.10.25'!E154 -> 31 | H16: ='WE 12.10.25'!E157 -> T1 | I16: ='WE 12.10.25'!$E$156 -> 7.13

Sheet Physical GVs
B2: Card ID | C2: Line Item ID | D2: Product Name | E2: Unit | F2: Card Unique Code | G2: Line Item Type | H2: Value | I2: Adjustment Date (UTC)
B3: 4426998 | C3: 12370252 | D3: Migration Product | E3: FIRE Steakhouse & Bar | F3: #6301190059386716510 | G3: Redemption | H3: -100 | I3: 45936.829
H4: =SUM(H3) -> -100
B7: Card ID | C7: Line Item ID | D7: Product Name | E7: Unit | F7: Card Unique Code | G7: Line Item Type | H7: Value | I7: Adjustment Date (UTC)
B8: 4423862 | C8: 12383221 | D8: Migration Product | E8: FIRE Steakhouse & Bar | F8: #6301190003516624137 | G8: Redemption | H8: -150 | I8: 45938.845
H9: =SUM(H8) -> -150
B12: Card ID | C12: Line Item ID | D12: Product Name | E12: Unit | F12: Card Unique Code | G12: Line Item Type | H12: Value | I12: Adjustment Date (UTC)
B13: 5752439 | C13: 12390316 | D13: In-Store Gift | E13: FIRE Steakhouse & Bar | F13: #6301190057458983869 | G13: Sale | H13: 150 | I13: 45939.876
H14: =SUM(H13) -> 150
B17: Card ID | C17: Line Item ID | D17: Product Name | E17: Unit | F17: Card Unique Code | G17: Line Item Type | H17: Value | I17: Adjustment Date (UTC)
B18: 4422777 | C18: 12399729 | D18: Migration Product | E18: FIRE Steakhouse & Bar | F18: #6301190015276724899 | G18: Redemption | H18: -200 | I18: 45940.922
H19: =SUM(H18) -> -200
B22: Card ID | C22: Line Item ID | D22: Product Name | E22: Unit | F22: Card Unique Code | G22: Line Item Type | H22: Value | I22: Adjustment Date (UTC)
B23: 5758256 | C23: 12408422 | D23: In-Store Gift | E23: FIRE Steakhouse & Bar | F23: #6301190096387333721 | G23: Sale | H23: 150 | I23: 45941.755
H24: =SUM(H23) -> 150
B27: Card ID | C27: Line Item ID | D27: Product Name | E27: Unit | F27: Card Unique Code | G27: Line Item Type | H27: Value | I27: Adjustment Date (UTC)
B28: 4936334 | C28: 12405055 | D28: In-Store Gift | E28: FIRE Steakhouse & Bar | F28: #6301190093583549481 | G28: Redemption | H28: -100 | I28: 45941.618
B29: 5489870 | C29: 12408981 | D29: In-Store Gift | E29: FIRE Steakhouse & Bar | F29: #6301190042940563040 | G29: Redemption | H29: -150 | I29: 45941.777
B30: 4428833 | C30: 12406767 | D30: Migration Product | E30: FIRE Steakhouse & Bar | F30: #6301190020055609691 | G30: Redemption | H30: -100 | I30: 45941.683
B31: 4424927 | C31: 12408182 | D31: Migration Product | E31: FIRE Steakhouse & Bar | F31: #6301190055310977756 | G31: Redemption | H31: -150 | I31: 45941.745
B32: 4423930 | C32: 12408582 | D32: Migration Product | E32: FIRE Steakhouse & Bar | F32: #6301190076488852225 | G32: Redemption | H32: -150 | I32: 45941.76
B33: 4420928 | C33: 12409443 | D33: Migration Product | E33: FIRE Steakhouse & Bar | F33: #6301190010207520490 | G33: Redemption | H33: -87.5 | I33: 45941.798
B34: 4425160 | C34: 12409666 | D34: Migration Product | E34: FIRE Steakhouse & Bar | F34: #6301190089545476078 | G34: Redemption | H34: -150 | I34: 45941.808
B35: 5318880 | C35: 12409289 | D35: Physical Gift Card | E35: FIRE Steakhouse & Bar | F35: #6301190001641737956 | G35: Redemption | H35: -150 | I35: 45941.79
B36: 5633644 | C36: 12410059 | D36: Physical Gift Card | E36: FIRE Steakhouse & Bar | F36: #6301190054681848654 | G36: Redemption | H36: -300 | I36: 45941.827
H37: =SUM(H28:H36) -> -1337.5
B40: Card ID | C40: Line Item ID | D40: Product Name | E40: Unit | F40: Card Unique Code | G40: Line Item Type | H40: Value | I40: Adjustment Date (UTC)
B41: 5760199 | C41: 12415483 | D41: In-Store Gift | E41: FIRE Steakhouse & Bar | F41: #6301190050592902028 | G41: Sale | H41: 100 | I41: 45942.575
B42: 5760283 | C42: 12415808 | D42: In-Store Gift | E42: FIRE Steakhouse & Bar | F42: #6301190006178973734 | G42: Sale | H42: 100 | I42: 45942.592
B43: 5760289 | C43: 12415831 | D43: In-Store Gift | E43: FIRE Steakhouse & Bar | F43: #6301190013523165867 | G43: Sale | H43: 150 | I43: 45942.593
H44: =SUM(H41:H43) -> 350
B46: Card ID | C46: Line Item ID | D46: Product Name | E46: Unit | F46: Card Unique Code | G46: Line Item Type | H46: Value | I46: Adjustment Date (UTC)
B47: 4447970 | C47: 12417243 | D47: Migration Product | E47: FIRE Steakhouse & Bar | F47: #6301190083751282973 | G47: Redemption | H47: -75 | I47: 45942.664
H48: =SUM(H47) -> -75
E52: Physical Sold | F52: =H14+H24+H44 -> 650 | G52: On Sage | H52: G2025 | I52: SP / F2025
E53: Physical Redeemed | F53: =-H4-H9-H19-H37-H48 -> 1862.5 | G53: On Sage | H53: GIFT2022 | I53: SC / F2025
E54: Digital Redeemed | F54: =-'Digital GVs'!H4-'Digital GVs'!H9-'Digital GVs'!H15-'Digital GVs'!H27-'Digital GVs'!H33 -> 2017.9 | G54: On Sage | H54: DGV2024 | I54: SC / F2025

Sheet Digital GVs
B2: Card ID | C2: Line Item ID | D2: Product Name | E2: Unit | F2: Card Unique Code | G2: Line Item Type | H2: Value | I2: Adjustment Date (UTC)
B3: 4375571 | C3: 12377109 | D3: Digital Gift Card | E3: FIRE Steakhouse & Bar | F3: #6301190092525046325 | G3: Redemption | H3: -265.3 | I3: 45937.888
H4: =SUM(H3) -> -265.3
B7: Card ID | C7: Line Item ID | D7: Product Name | E7: Unit | F7: Card Unique Code | G7: Line Item Type | H7: Value | I7: Adjustment Date (UTC)
B8: 5191979 | C8: 12389068 | D8: Digital Gift Card | E8: FIRE Steakhouse & Bar | F8: #6301190044666179613 | G8: Redemption | H8: -200 | I8: 45939.75
H9: =SUM(H8) -> -200
B12: Card ID | C12: Line Item ID | D12: Product Name | E12: Unit | F12: Card Unique Code | G12: Line Item Type | H12: Value | I12: Adjustment Date (UTC)
B13: 5753809 | C13: 12396828 | D13: Digital Gift Card | E13: FIRE Steakhouse & Bar | F13: #6301190072232221197 | G13: Redemption | H13: -100 | I13: 45940.731
B14: 5653721 | C14: 12397486 | D14: Digital Gift Card | E14: FIRE Steakhouse & Bar | F14: #6301190089639218394 | G14: Redemption | H14: -100 | I14: 45940.767
H15: =SUM(H13:H14) -> -200
B18: Card ID | C18: Line Item ID | D18: Product Name | E18: Unit | F18: Card Unique Code | G18: Line Item Type | H18: Value | I18: Adjustment Date (UTC)
B19: 4556882 | C19: 12405592 | D19: Digital Gift Card | E19: FIRE Steakhouse & Bar | F19: #6301190097930998804 | G19: Redemption | H19: -100 | I19: 45941.64
B20: 4710989 | C20: 12405654 | D20: Digital Gift Card | E20: FIRE Steakhouse & Bar | F20: #6301190001698208000 | G20: Redemption | H20: -50 | I20: 45941.642
B21: 5612751 | C21: 12407490 | D21: Digital Gift Card | E21: FIRE Steakhouse & Bar | F21: #6301190052000863628 | G21: Redemption | H21: -191.9 | I21: 45941.717
B22: 5648255 | C22: 12410003 | D22: Digital Gift Card | E22: FIRE Steakhouse & Bar | F22: #6301190061616225189 | G22: Redemption | H22: -175 | I22: 45941.824
B23: 5198942 | C23: 12410067 | D23: Digital Gift Card | E23: FIRE Steakhouse & Bar | F23: #6301190028778231966 | G23: Redemption | H23: -190.9 | I23: 45941.827
B24: 5246478 | C24: 12410267 | D24: Digital Gift Card | E24: FIRE Steakhouse & Bar | F24: #6301190028046755291 | G24: Redemption | H24: -150 | I24: 45941.835
B25: 4617256 | C25: 12406450 | D25: Digital Gift Card | E25: FIRE Steakhouse & Bar | F25: #6301190042722848460 | G25: Redemption | H25: -150.9 | I25: 45941.673
B26: 4651307 | C26: 12410401 | D26: Digital Gift Card | E26: FIRE Steakhouse & Bar | F26: #6301190047366728308 | G26: Redemption | H26: -100 | I26: 45941.843
H27: =SUM(H19:H26) -> -1108.7
B30: Card ID | C30: Line Item ID | D30: Product Name | E30: Unit | F30: Card Unique Code | G30: Line Item Type | H30: Value | I30: Adjustment Date (UTC)
B31: 5708493 | C31: 12418821 | D31: Digital Gift Card | E31: FIRE Steakhouse & Bar | F31: #6301190002476999307 | G31: Redemption | H31: -143.9 | I31: 45942.777
B32: 4396675 | C32: 12419301 | D32: Digital Gift Card | E32: FIRE Steakhouse & Bar | F32: #6301190053522980411 | G32: Redemption | H32: -100 | I32: 45942.826
H33: =SUM(H31:H32) -> -243.9

Sheet CC bank 
P1: 900017 | Q1: 28418820 | R1: CURRENT ACCOUNTS | S1: EUR | T1: 45022 | V1: OPENING BALANCE | X1: 0
P2: 900017 | Q2: 28418820 | R2: CURRENT ACCOUNTS | S2: EUR | T2: 45027 | V2: TO BANQUETING FOOD SY | W2: -45114.56
E3: CC HIT MY BANK | P3: 900017 | Q3: 28418820 | R3: CURRENT ACCOUNTS | S3: EUR | T3: 45027 | V3: DIAGEO IRELAN SEPA | W3: -1038.89
P4: 900017 | Q4: 28418820 | R4: CURRENT ACCOUNTS | S4: EUR | T4: 45027 | V4: OVATION IRELANDINV SP | X4: 4500
E5: Monday | F5: Tuesday | G5: Wednesday | H5: Thursday | I5: Friday | J5: Saturday | K5: Sunday | N5: =200*5 -> 1000 | P5: 900017 | Q5: 28418820 | R5: CURRENT ACCOUNTS | S5: EUR | T5: 45027 | V5: EMS679040922420030 SP | X5: 136.4
D6: DINNER | E6: 45936 | F6: =E6+1 -> 45937 | G6: =F6+1 -> 45938 | H6: =G6+1 -> 45939 | I6: =H6+1 -> 45940 | J6: =I6+1 -> 45941 | K6: =J6+1 -> 45942 | P6: 900017 | Q6: 28418820 | R6: CURRENT ACCOUNTS | S6: EUR | T6: 45027 | V6: EMS575040922420032 SP | X6: 7183
D7: BANK | E7: =F6 -> 45937 | F7: =G6 -> 45938 | G7: =H6 -> 45939 | H7: =I6 -> 45940 | I7: =K6+1 -> 45943 | J7: =K6+1 -> 45943 | K7: =I7 -> 45943 | P7: 900017 | Q7: 28418820 | R7: CURRENT ACCOUNTS | S7: EUR | T7: 45027 | V7: EMS577040922420034 SP | X7: 6240.61
E8: 5975.3 | F8: 5510.22 | G8: 191.1 | H8: 6928.18 | I8: 474.86 | J8: 15333.16 | K8: 9945.92 | P8: 900017 | Q8: 28418820 | R8: CURRENT ACCOUNTS | S8: EUR | T8: 45027 | V8: EMS574040900240032 SP | X8: 5167.23
E9: 271.57 | F9: 4920.66 | G9: 6697.11 | H9: 3717.94 | I9: 5651.58 | J9: 10289.76 | K9: 5419.2 | P9: 900017 | Q9: 28418820 | R9: CURRENT ACCOUNTS | S9: EUR | T9: 45027 | V9: EMS647040900240031 SP | X9: 7627.99
E10: 4537.42 | F10: 65 | G10: 6668.47 | H10: 156.28 | I10: 9260.75 | J10: 7676.71 | K10: 5626.53 | P10: 900017 | Q10: 28418820 | R10: CURRENT ACCOUNTS | S10: EUR | T10: 45027 | V10: EMS751040900240029 SP | X10: 1096.57
E11: 7227.14 | F11: 2439.87 | G11: 7352.75 | H11: 1238.46 | I11: 9960.55 | J11: 9672.54 | K11: 6170.17 | P11: 900017 | Q11: 28418820 | R11: CURRENT ACCOUNTS | S11: EUR | T11: 45027 | V11: EMS648040922420031 SP | X11: 5769.43
E12: 4772.26 | F12: 4819.05 | G12: 2821.13 | H12: 37 | I12: 7.85 | J12: 2817.79 | K12: 262.49 | P12: 900017 | Q12: 28418820 | R12: CURRENT ACCOUNTS | S12: EUR | T12: 45027 | V12: EMS749040700140029 SP | X12: 576.61
E13: 33 | F13: 96 | G13: 4.71 | H13: 10327.74 | I13: 4277.86 | J13: 132.38 | K13: 367.62 | P13: 900017 | Q13: 28418820 | R13: CURRENT ACCOUNTS | S13: EUR | T13: 45027 | V13: EMS648040700140033 SP | X13: 4262.35
P14: 900017 | Q14: 28418820 | R14: CURRENT ACCOUNTS | S14: EUR | T14: 45027 | V14: EMS645040700140031 SP | X14: 4439.37
P15: 900017 | Q15: 28418820 | R15: CURRENT ACCOUNTS | S15: EUR | T15: 45027 | V15: 9FJBPNMLHFJLEVKK9U SP | X15: 808.78
P16: 900017 | Q16: 28418820 | R16: CURRENT ACCOUNTS | S16: EUR | T16: 45027 | V16: EMS676040723500030 SP | X16: 206
P17: 900017 | Q17: 28418820 | R17: CURRENT ACCOUNTS | S17: EUR | T17: 45027 | V17: EMS649040723500033 SP | X17: 4244.25
E18: =SUM(E8:E17) -> 22816.69 | F18: =SUM(F8:F17) -> 17850.8 | G18: =SUM(G8:G17) -> 23735.27 | H18: =SUM(H8:H17) -> 22405.6 | I18: =SUM(I8:I17) -> 29633.45 | J18: =SUM(J8:J17) -> 45922.34 | K18: =SUM(K8:K17) -> 27791.93 | L18: =SUM(E18:K18) -> 190156.08 | P18: 900017 | Q18: 28418820 | R18: CURRENT ACCOUNTS | S18: EUR | T18: 45027 | V18: EMS649041023500031 SP | X18: 2757.9
E19: 22816.69 | F19: 17850.8 | G19: 23735.27 | H19: 22405.6 | I19: 29633.45 | J19: 45922.34 | K19: 27791.93 | L19: =SUM(E19:K19) -> 190156.08 | P19: 900017 | Q19: 28418820 | R19: CURRENT ACCOUNTS | S19: EUR | T19: 45027 | V19: EMS576041023500032 SP | X19: 5957.2
E20: =E18-E19 -> 0 | F20: =F18-F19 -> 0 | G20: =G18-G19 -> 0 | H20: =H18-H19 -> 0 | I20: =I18-I19 -> 0 | J20: =J18-J19 -> 0 | K20: =K18-K19 -> 0 | L20: =L18-L19 -> 0 | P20: 900017 | Q20: 28418820 | R20: CURRENT ACCOUNTS | S20: EUR | T20: 45027 | V20: EMS752040922420029 SP | X20: 243.5
P21: 900017 | Q21: 28418820 | R21: CURRENT ACCOUNTS | S21: EUR | T21: 45027 | V21: EMS677040804010030 SP | X21: 7
P22: 900017 | Q22: 28418820 | R22: CURRENT ACCOUNTS | S22: EUR | T22: 45027 | V22: EMS651040922420033 SP | X22: 6599.93
C23: cash back | P23: 900017 | Q23: 28418820 | R23: CURRENT ACCOUNTS | S23: EUR | T23: 45027 | V23: EMS576040900240034 SP | X23: 6451.97
C24: ID/Note | P24: 900017 | Q24: 28418820 | R24: CURRENT ACCOUNTS | S24: EUR | T24: 45027 | V24: EMS678040900240030 SP | X24: 49.1
P25: 900017 | Q25: 28418820 | R25: CURRENT ACCOUNTS | S25: EUR | T25: 45027 | V25: EMS574040700140034 SP | X25: 6074.6
P26: 900017 | Q26: 28418820 | R26: CURRENT ACCOUNTS | S26: EUR | T26: 45027 | V26: EMS294040900402381 SP | X26: 100
P27: 900017 | Q27: 28418820 | R27: CURRENT ACCOUNTS | S27: EUR | T27: 45027 | V27: EMS675040700140030 SP | X27: 140
P28: 900017 | Q28: 28418820 | R28: CURRENT ACCOUNTS | S28: EUR | T28: 45027 | V28: EMS572040700140032 SP | X28: 6121.91
P29: 900017 | Q29: 28418820 | R29: CURRENT ACCOUNTS | S29: EUR | T29: 45027 | V29: EMS646040723500031 SP | X29: 7288.22
P30: 900017 | Q30: 28418820 | R30: CURRENT ACCOUNTS | S30: EUR | T30: 45027 | V30: EMS575040723500034 SP | X30: 4499.41
P31: 900017 | Q31: 28418820 | R31: CURRENT ACCOUNTS | S31: EUR | T31: 45027 | V31: EMS750040723500029 SP | X31: 38.1
P32: 900017 | Q32: 28418820 | R32: CURRENT ACCOUNTS | S32: EUR | T32: 45027 | V32: EMS573040723500032 SP | X32: 4469.36
P33: 900017 | Q33: 28418820 | R33: CURRENT ACCOUNTS | S33: EUR | T33: 45027 | V33: EMS652041023500033 SP | X33: 3972.29
P34: 900017 | Q34: 28418820 | R34: CURRENT ACCOUNTS | S34: EUR | T34: 45027 | V34: EMS578041023500034 SP | X34: 2012.4
P35: 900017 | Q35: 28418820 | R35: CURRENT ACCOUNTS | S35: EUR | T35: 45027 | V35: EMS753041023500029 SP | X35: 153.56
P36: 900017 | Q36: 28418820 | R36: CURRENT ACCOUNTS | S36: EUR | T36: 45027 | V36: EMS680041023500030 SP | X36: 124.4

Sheet CC TIPS
A3: Monday | B3: 45936
A5: Transaction Type | B5: Total Tips Collected | C5: Total Transaction Amount
A6: Credit/Debit (89) | B6: 1434.43 | C6: 22816.69
A7: Mastercard (39) | B7: 513.69 | C7: 12215.12
A8: Amex (13) | B8: 285.64 | C8: 2590.77
A9: Visa (37) | B9: 635.1 | C9: 8010.8
A12: Tuesday | B12: =B3+1 -> 45937
A14: Transaction Type | B14: Total Tips Collected | C14: Total Transaction Amount
A15: Credit/Debit (59) | B15: 878.79 | C15: 17850.8
A16: Visa (33) | B16: 346.19 | C16: 7643.37
A17: Amex (8) | B17: 204.98 | C17: 3192.03
A18: Mastercard (16) | B18: 327.62 | C18: 6898.5
A19: Maestro (2) | B19: 0 | C19: 116.9
A23: Wednesday | B23: =B12+1 -> 45938
A25: Transaction Type | B25: Total Tips Collected | C25: Total Transaction Amount
A26: Credit/Debit (62) | B26: 916.57 | C26: 23725.27
A27: Visa (39) | B27: 447.08 | C27: 10061.08
A28: Mastercard (14) | B28: 229.05 | C28: 9054.46
A29: Amex (8) | B29: 225.18 | C29: 4467.27
A30: Debit (1) | B30: 15.26 | C30: 142.46
A33: Thursday | B33: =B23+1 -> 45939
A34: Transaction Type | B34: Total Tips Collected | C34: Total Transaction Amount
A35: Credit/Debit (79) | B35: 1181.45 | C35: 22405.6
A36: Mastercard (24) | B36: 284.93 | C36: 6892.92
A37: Visa (45) | B37: 539.98 | C37: 11076.44
A38: Amex (9) | B38: 330.55 | C38: 4193.65
A39: Maestro (1) | B39: 25.99 | C39: 242.59
A41: Friday | B41: =B33+1 -> 45940
A43: Transaction Type | B43: Total Tips Collected | C43: Total Transaction Amount
A44: Credit/Debit (116) | B44: 2023.06 | C44: 29633.45
A45: Mastercard (42) | B45: 807.68 | C45: 11273.85
A46: Visa (62) | B46: 909.83 | C46: 12076.84
A47: Amex (9) | B47: 256.14 | C47: 5708.55
A48: Discover (1) | B48: 32.31 | C48: 247.71
A49: Maestro (2) | B49: 17.1 | C49: 326.5
A51: Saturday | B51: =B41+1 -> 45941
A53: Transaction Type | B53: Total Tips Collected | C53: Total Transaction Amount
A54: Credit/Debit (283) | B54: 2711.2 | C54: 45922.34
A55: Mastercard (79) | B55: 567.15 | C55: 15587.48
A56: Visa (195) | B56: 1939.73 | C56: 27677.43
...

Sheet CC Rec 06.10
A1: Date | B1: Payment | C1: tip included | D1: Total | E1: Net | H1: Card Payment | I1: Trans | J1: Date | K1: Time | L1: Value
A2: 10/6/25, 11:13 pm | B2: Mastercard 7646 | C2: 0 | D2: 225 | E2: =D2-C2 -> 225 | H2: Received | I2: 236171 | J2: 45936 | K2: 0.96813657 | L2: 218.9 | M2: =E2-L2 -> 6.1
A3: 10/6/25, 10:10 pm | B3: Visa 7698 | C3: 33.6 | D3: 201.6 | E3: =D3-C3 -> 168 | H3: Received | I3: 236159 | J3: 45936 | K3: 0.95256944 | L3: 168 | M3: =(E3+E4+E5)-(L3+L4+L5) -> 2.7
A4: 10/6/25, 10:11 pm | B4: Visa 0335 | C4: 33.6 | D4: 201.6 | E4: =D4-C4 -> 168 | H4: Received | I4: 236159 | J4: 45936 | K4: 0.95262731 | L4: 168
A5: 10/6/25, 10:12 pm | B5: Mastercard 9567 | C5: 0 | D5: 168 | E5: =D5-C5 -> 168 | H5: Received | I5: 236159 | J5: 45936 | K5: 0.95267361 | L5: 165.3
A6: 10/6/25, 10:48 pm | B6: Mastercard 4543 | C6: 0 | D6: 1849.51 | E6: =D6-C6 -> 1849.51 | H6: Received | I6: 236157 | J6: 45936 | K6: 0.95136574 | L6: 1849.51
A7: 10/6/25, 9:51 pm | B7: Mastercard 5555 | C7: 0 | D7: 1798.65 | E7: =D7-C7 -> 1798.65 | H7: Received | I7: 236144 | J7: 45936 | K7: 0.9191088 | L7: 1798.65
A8: 10/6/25, 10:57 pm | B8: Visa 8832 | C8: 0 | D8: 1290 | E8: =D8-C8 -> 1290 | H8: Received | I8: 236163 | J8: 45936 | K8: 0.96479167 | L8: 1290
A9: 10/6/25, 8:58 pm | B9: Mastercard 4423 | C9: 0 | D9: 993.49 | E9: =D9-C9 -> 993.49 | H9: Received | I9: 236131 | J9: 45936 | K9: 0.90672454 | L9: 993.49
A10: 10/6/25, 8:23 pm | B10: Mastercard 0893 | C10: 0 | D10: 731.48 | E10: =D10-C10 -> 731.48 | H10: Received | I10: 236104 | J10: 45936 | K10: 0.85435185 | L10: 731.48
A11: 10/6/25, 10:33 pm | B11: Visa 8456 | C11: 0 | D11: 681.3 | E11: =D11-C11 -> 681.3 | H11: Received | I11: 236171 | J11: 45936 | K11: 0.95678241 | L11: 694.01
A12: 10/6/25, 9:36 pm | B12: Mastercard 6466 | C12: 0 | D12: 524.36 | E12: =D12-C12 -> 524.36 | H12: Received | I12: 236164 | J12: 45936 | K12: 0.94068287 | L12: 681.3
A13: 10/6/25, 9:23 pm | B13: Amex 3009 | C13: 65.37 | D13: 501.17 | E13: =D13-C13 -> 435.8 | H13: Received | I13: 236136 | J13: 45936 | K13: 0.90145833 | L13: 524.36
A14: 10/6/25, 7:37 pm | B14: Visa 4736 | C14: 40 | D14: 470.8 | E14: =D14-C14 -> 430.8 | H14: Received | I14: 236147 | J14: 45936 | K14: 0.95584491 | L14: 435.8
A15: 10/6/25, 9:48 pm | B15: Amex 4002 | C15: 47.36 | D15: 442.06 | E15: =D15-C15 -> 394.7 | H15: Received | I15: 236083 | J15: 45936 | K15: 0.84034722 | L15: 430.8
... A90: 10/6/25, 10:15 pm | B90: Visa 4614 | C90: 0 | D90: 0.68 | E90: =D90-C90 -> 0.68 | H90: Received | I90: 236072 | J90: 45936 | K90: 0.59678241 | L90: 1.09
H91: Received | I91: 236184 | J91: 45936 | K91: 0.92456019 | L91: 0.68
H92: Received | I92: 236171 | J92: 45936 | K92: 0.95712963 | L92: -694.01

Sheet CC Rec 10.10
A1: Card Payment | B1: Trans | C1: Date | D1: Time | E1: Value | F1: tips | H1: Date | I1: Payment | J1: tip included | K1: Total | L1: Net
A2: Received | B2: 236665 | C2: 45940 | D2: 0.99649306 | E2: 195.7 | F2: 4.3 | H2: 10/10/25, 11:52 pm | I2: Visa 8984 | J2: =74.3 -> 74.3 | K2: 220 | L2: =K2-J2 -> 145.7
A3: Received | B3: 236593 | C3: 45940 | D3: 0.92422454 | E3: 48.3 | H3: 10/10/25, 9:53 pm | I3: Visa 8358 | J3: 36.7 | K3: 85 | L3: =K3-J3 -> 48.3
A4: Received | B4: 236579 | C4: 45940 | D4: 0.97561343 | E4: 2076.64 | H4: 10/10/25, 10:27 pm | I4: Mastercard 6348 | J4: 50 | K4: 50.01 | L4: =K4-J4 -> 0.01
A5: Received | B5: 236621 | C5: 45940 | D5: 0.9399537 | E5: 1742.74 | H5: 10/10/25, 11:24 pm | I5: Mastercard 2475 | J5: 0 | K5: 2076.64 | L5: =K5-J5 -> 2076.64
A6: Received | B6: 236637 | C6: 45940 | D6: 0.9921412 | E6: 1238.74 | H6: 10/10/25, 10:32 pm | I6: Amex 7002 | J6: 58 | K6: 1800.74 | L6: =K6-J6 -> 1742.74
A7: Received | B7: 236521 | C7: 45940 | D7: 0.79510417 | E7: 1003.73 | H7: 10/10/25, 11:35 pm | I7: Amex 3003 | J7: 0 | K7: 1238.74 | L7: =K7-J7 -> 1238.74
A8: Received | B8: 236650 | C8: 45940 | D8: 0.96261574 | E8: 667.91 | H8: 10/10/25, 7:01 pm | I8: Amex 2001 | J8: 0 | K8: 1003.73 | L8: =K8-J8 -> 1003.73
A9: Received | B9: 236580 | C9: 45940 | D9: 0.88925926 | E9: 613.1 | H9: 10/10/25, 11:00 pm | I9: Visa 4759 | J9: 0 | K9: 667.91 | L9: =K9-J9 -> 667.91
A10: Received | B10: 236571 | C10: 45940 | D10: 0.8584375 | E10: 488.9 | H10: 10/10/25, 9:09 pm | I10: Mastercard 3550 | J10: 122.62 | K10: 735.72 | L10: =K10-J10 -> 613.1
A11: Received | B11: 236601 | C11: 45940 | D11: 0.92731481 | E11: 480.4 | H11: 10/10/25, 8:34 pm | I11: Visa 3892 | J11: 73.34 | K11: 562.24 | L11: =K11-J11 -> 488.9
A12: Received | B12: 236527 | C12: 45940 | D12: 0.79524306 | E12: 468 | H12: 10/10/25, 10:12 pm | I12: Mastercard 1347 | J12: 72.06 | K12: 552.46 | L12: =K12-J12 -> 480.4
A13: Received | B13: 236605 | C13: 45940 | D13: 0.92357639 | E13: 451.4 | H13: 10/10/25, 6:45 pm | I13: Mastercard 4795 | J13: 0 | K13: 468 | L13: =K13-J13 -> 468
A14: Received | B14: 236606 | C14: 45940 | D14: 0.95395833 | E14: 438.1 | H14: 10/10/25, 9:59 pm | I14: Visa 5413 | J14: 54.17 | K14: 505.57 | L14: =K14-J14 -> 451.4
... A117: Received | B117: 236687 | C117: 45940 | D117: 0.90804398 | E117: 8 | H117: 10/10/25, 10:58 pm | I117: Visa 3329 | J117: 0 | K117: 7.85 | L117: =K117-J117 -> 7.85
A118: Received | B118: 236693 | C118: 45940 | D118: 0.96321759 | E118: 7.85 | L118: =SUM(L2:L117) -> 27610.39
A119: Received | B119: 236593 | C119: 45940 | D119: 0.92400463 | E119: -48.3 | L119: =L118-E121 -> -50
A120: Received | B120: 236593 | C120: 45940 | D120: 0.9240162 | E120: -85
E121: =SUM(E2:E120) -> 27660.39

Sheet CC Rec 12.10
A1: Card Payment | B1: Trans | C1: Date | D1: Time | E1: Value | F1: Tips | I1: Date | J1: Payment | K1: tip included | L1: Total | M1: Net
A2: Received | B2: 237075 | C2: 45942 | D2: 0.75769676 | E2: 350 | I2: 10/12/25, 5:58 pm | J2: Mastercard 3330 | K2: 0 | L2: 350 | M2: =L2-K2 -> 350
A3: Received | B3: 237075 | C3: 45942 | D3: 0.75777778 | E3: 326.8 | F3: 23.2 | I3: 10/12/25, 5:58 pm | J3: Visa 5338 | K3: 0 | L3: 350 | M3: =L3-K3 -> 350
A4: Received | B4: 237065 | C4: 45942 | D4: 0.77284722 | E4: 241.2 | I4: 10/12/25, 6:30 pm | J4: Mastercard 7779 | K4: 0 | L4: 265 | M4: =L4-K4 -> 265 | N4: =M4-E4 -> 23.8
A5: Received | B5: 237051 | C5: 45942 | D5: 0.58938657 | E5: 1.09 | I5: 10/12/25, 7:52 pm | J5: Visa 6023 | K5: 9.99 | L5: 10 | M5: =L5-K5 -> 0.01
A6: Received | B6: 237140 | C6: 45942 | D6: 0.89896991 | E6: 1320.3 | I6: 10/12/25, 9:32 pm | J6: Visa 8206 | K6: 180 | L6: 1500.3 | M6: =L6-K6 -> 1320.3
A7: Received | B7: 237164 | C7: 45942 | D7: 0.92582176 | E7: 1187.66 | I7: 10/12/25, 10:10 pm | J7: Amex 5024 | K7: 0 | L7: 1187.66 | M7: =L7-K7 -> 1187.66
A8: Received | B8: 237060 | C8: 45942 | D8: 0.71184028 | E8: 1018.46 | I8: 10/12/25, 5:03 pm | J8: Visa 0696 | K8: 0 | L8: 1018.46 | M8: =L8-K8 -> 1018.46
A9: Received | B9: 237172 | C9: 45942 | D9: 0.95613426 | E9: 665.35 | I9: 10/12/25, 10:54 pm | J9: Mastercard 6715 | K9: 0 | L9: 665.35 | M9: =L9-K9 -> 665.35
A10: Received | B10: 237092 | C10: 45942 | D10: 0.78993056 | E10: 617.4 | I10: 10/12/25, 6:52 pm | J10: Visa 9785 | K10: 40 | L10: 657.4 | M10: =L10-K10 -> 617.4
A11: Received | B11: 237169 | C11: 45942 | D11: 0.96130787 | E11: 614 | I11: 10/12/25, 11:03 pm | J11: Visa 7269 | K11: 0 | L11: 614 | M11: =L11-K11 -> 614
A12: Received | B12: 237150 | C12: 45942 | D12: 0.88528935 | E12: 451.3 | I12: 10/12/25, 9:05 pm | J12: Visa 8737 | K12: 48.7 | L12: 500 | M12: =L12-K12 -> 451.3
A13: Received | B13: 237105 | C13: 45942 | D13: 0.82233796 | E13: 447.19 | I13: 10/12/25, 7:43 pm | J13: Visa 5007 | K13: 0 | L13: 447.19 | M13: =L13-K13 -> 447.19
A14: Received | B14: 237161 | C14: 45942 | D14: 0.92474537 | E14: 426.5 | I14: 10/12/25, 10:10 pm | J14: Visa 3898 | K14: 23.5 | L14: 450 | M14: =L14-K14 -> 426.5
A15: Received | B15: 237071 | C15: 45942 | D15: 0.70898148 | E15: 413.7 | I15: 10/12/25, 4:53 pm | J15: Visa 5267 | K15: 0 | L15: 413.7 | M15: =L15-K15 -> 413.7
A16: Received | B16: 237155 | C16: 45942 | D16: 0.89668981 | E16: 382.8 | I16: 10/12/25, 9:30 pm | J16: Mastercard 8811 | K16: 57.42 | L16: 440.22 | M16: =L16-K16 -> 382.8
... A112: Received | B112: 237142 | C112: 45942 | D112: 0.88076389 | E112: 72.9 | I112: 10/12/25, 9:07 pm | J112: Visa 0870 | K112: 14.58 | L112: 87.48 | M112: =L112-K112 -> 72.9
A113: Received | B113: 237152 | C113: 45942 | D113: 0.92803241 | E113: 69.4 | F113: 27 | I113: 10/12/25, 10:10 pm | J113: Mastercard 6213 | K113: 26.6 | L113: 96 | M113: =L113-K113 -> 69.4
A114: Received | B114: 237130 | C114: 45942 | D114: 0.83429398 | E114: 68.5 | I114: 10/12/25, 7:52 pm | J114: Visa 6023 | K114: 0.1 | L114: 68.6 | M114: =L114-K114 -> 68.5
A115: Received | B115: 237089 | C115: 45942 | D115: 0.7696412 | E115: 60 | I115: 10/12/25, 6:24 pm | J115: Visa 3407 | K115: 0 | L115: 60 | M115: =L115-K115 -> 60
A116: Received | B116: 237089 | C116: 45942 | D116: 0.76958333 | E116: 60 | I116: 10/12/25, 6:25 pm | J116: Visa 5699 | K116: 0 | L116: 60 | M116: =L116-K116 -> 60
A117: Received | B117: 237089 | C117: 45942 | D117: 0.76951389 | E117: 60 | I117: 10/12/25, 6:26 pm | J117: Mastercard 9070 | K117: 0 | L117: 60 | M117: =L117-K117 -> 60
A118: Received | B118: 237089 | C118: 45942 | D118: 0.76946759 | E118: 60 | I118: 10/12/25, 6:27 pm | J118: Mastercard 7736 | K118: 0 | L118: 60 | M118: =L118-K118 -> 60
A119: Received | B119: 237076 | C119: 45942 | D119: 0.70768519 | E119: 53.5 | I119: 10/12/25, 4:57 pm | J119: Visa 1403 | K119: 0 | L119: 53.5 | M119: =L119-K119 -> 53.5
A120: Received | B120: 237194 | C120: 45942 | D120: 0.91290509 | E120: 49.5 | I120: 10/12/25, 9:42 pm | J120: Mastercard 7047 | K120: 0 | L120: 49.5 | M120: =L120-K120 -> 49.5
A121: Received | B121: 237129 | C121: 45942 | D121: 0.78700231 | E121: 15 | I121: 10/12/25, 6:53 pm | J121: Visa 2251 | K121: 0 | L121: 15 | M121: =L121-K121 -> 15
A122: Received | B122: 237200 | C122: 45942 | D122: 0.9025 | E122: 12.49 | I122: 10/12/25, 9:40 pm | J122: Visa 3832 | K122: 0 | L122: 12.49 | M122: =L122-K122 -> 12.49
A123: Received | B123: 237144 | C123: 45942 | D123: 0.88984954 | E123: 9.6 | I123: 10/12/25, 9:20 pm | J123: Visa 3352 | K123: 10 | L123: 19.6 | M123: =L123-K123 -> 9.6
A124: Received | B124: 237171 | C124: 45942 | D124: 0.88350694 | E124: 4 | I124: 10/12/25, 9:11 pm | J124: Visa 2251 | K124: 0 | L124: 4 | M124: =L124-K124 -> 4
A125: Received | B125: 237201 | C125: 45942 | D125: 0.92719907 | E125: 1.2 | I125: 10/12/25, 2:08 pm | J125: Visa 7091 | K125: 0 | L125: 1.9 | M125: =L125-K125 -> 1.9
I126: 10/12/25, 9:55 pm | J126: Visa 9844 | K126: 0 | L126: 1.2 | M126: =L126-K126 -> 1.2
E127: =SUM(E2:E126) -> 25660.92 | M127: =SUM(M2:M126) -> 25708.64
M128: =M127-E127 -> 47.72
